<?xml version="1.0" encoding="utf-8"?>
<!-- Piper X Robotic Arm - MuJoCo MJCF Model
     Converted from URDF: piper_ros/src/piper_description/urdf/piper_description.urdf -->
<mujoco model="piper">
  <compiler angle="radian" meshdir="piper_ros/src/piper_description/meshes"/>

  <option timestep="0.002" gravity="0 0 -9.81"/>

  <default>
    <joint damping="50" armature="0.5"/>
    <geom rgba="0.8 0.82 0.93 1" friction="1 0.005 0.0001"/>
    <motor ctrlrange="-100 100" ctrllimited="true"/>
  </default>

  <asset>
    <mesh name="base_link" file="base_link.STL"/>
    <mesh name="link1" file="link1.STL"/>
    <mesh name="link2" file="link2.STL"/>
    <mesh name="link3" file="link3.STL"/>
    <mesh name="link4" file="link4.STL"/>
    <mesh name="link5" file="link5.STL"/>
    <mesh name="link6" file="link6.STL"/>
    <mesh name="gripper_base" file="gripper_base.STL"/>
    <mesh name="link7" file="link7.STL"/>
    <mesh name="link8" file="link8.STL"/>
    <texture type="skybox" builtin="gradient" rgb1="0.3 0.5 0.7" rgb2="0 0 0" width="512" height="512"/>
    <texture name="grid" type="2d" builtin="checker" rgb1="0.2 0.2 0.2" rgb2="0.3 0.3 0.3" width="512" height="512"/>
    <material name="grid" texture="grid" texrepeat="8 8" reflectance="0.2"/>
  </asset>

  <worldbody>
    <light directional="true" diffuse="0.8 0.8 0.8" specular="0.2 0.2 0.2" pos="0 0 5" dir="0 0 -1"/>
    <light directional="true" diffuse="0.4 0.4 0.4" specular="0.1 0.1 0.1" pos="0 5 3" dir="0 -1 -0.5"/>

    <geom name="floor" type="plane" size="2 2 0.1" material="grid"/>

    <!-- Base mounted on table -->
    <body name="base_link" pos="0 0 0.5">
      <inertial pos="-0.00474 0.00003 0.0415" mass="1.02"
                diaginertia="0.00283 0.00267 0.00090"/>
      <geom type="mesh" mesh="base_link"/>

      <!-- Joint 1: Base rotation -->
      <body name="link1" pos="0 0 0.123">
        <inertial pos="0.00012 0.00010 -0.00439" mass="0.71"
                  diaginertia="0.00049 0.00040 0.00044"/>
        <joint name="joint1" type="hinge" axis="0 0 1"
               range="-2.618 2.618" damping="80"/>
        <geom type="mesh" mesh="link1"/>

        <!-- Joint 2: Shoulder -->
        <body name="link2" pos="0 0 0" euler="1.5708 -0.1359 -3.1416">
          <inertial pos="0.199 -0.011 0.001" mass="1.17"
                    diaginertia="0.0679 0.0677 0.00117"/>
          <joint name="joint2" type="hinge" axis="0 0 1"
                 range="0 3.14" damping="100"/>
          <geom type="mesh" mesh="link2"/>

          <!-- Joint 3: Elbow -->
          <body name="link3" pos="0.28503 0 0" euler="0 0 -1.7939">
            <inertial pos="-0.020 -0.134 -0.0005" mass="0.5"
                      diaginertia="0.0138 0.0136 0.00045"/>
            <joint name="joint3" type="hinge" axis="0 0 1"
                   range="-2.967 0" damping="80"/>
            <geom type="mesh" mesh="link3"/>

            <!-- Joint 4: Wrist 1 -->
            <body name="link4" pos="-0.021984 -0.25075 0" euler="1.5708 0 0">
              <inertial pos="-0.0001 0.0009 -0.005" mass="0.38"
                        diaginertia="0.00019 0.00019 0.00015"/>
              <joint name="joint4" type="hinge" axis="0 0 1"
                     range="-1.745 1.745" damping="40"/>
              <geom type="mesh" mesh="link4"/>

              <!-- Joint 5: Wrist 2 -->
              <body name="link5" pos="0 0 0" euler="-1.5708 0 0">
                <inertial pos="-0.00004 -0.0566 -0.0037" mass="0.383"
                          diaginertia="0.00166 0.00164 0.00019"/>
                <joint name="joint5" type="hinge" axis="0 0 1"
                       range="-1.22 1.22" damping="40"/>
                <geom type="mesh" mesh="link5"/>

                <!-- Joint 6: Wrist 3 -->
                <body name="link6" pos="0.0000883 -0.091 0" euler="1.5708 0 0">
                  <inertial pos="-0.00009 0.00001 -0.002" mass="0.007"
                            diaginertia="0.000001 0.000001 0.000001"/>
                  <joint name="joint6" type="hinge" axis="0 0 1"
                         range="-2.0944 2.0944" damping="30"/>
                  <geom type="mesh" mesh="link6" rgba="0.9 0.92 0.93 1"/>

                  <!-- Gripper Base (fixed to link6) -->
                  <body name="gripper_base" pos="0 0 0">
                    <inertial pos="-0.0002 0.00008 0.032" mass="0.45"
                              diaginertia="0.00093 0.00071 0.00039"/>
                    <geom type="mesh" mesh="gripper_base"/>

                    <!-- Gripper Finger 1 (left) -->
                    <body name="link7" pos="0 0 0.1358" euler="1.5708 0 0">
                      <inertial pos="0.00065 -0.049 0.0097" mass="0.025"
                                diaginertia="0.000074 0.000075 0.000008"/>
                      <joint name="joint7" type="slide" axis="0 0 1"
                             range="0 0.035" damping="1"/>
                      <geom type="mesh" mesh="link7"/>
                    </body>

                    <!-- Gripper Finger 2 (right) -->
                    <body name="link8" pos="0 0 0.1358" euler="1.5708 0 -3.1416">
                      <inertial pos="0.00065 -0.049 0.0097" mass="0.025"
                                diaginertia="0.000074 0.000075 0.000008"/>
                      <joint name="joint8" type="slide" axis="0 0 -1"
                             range="-0.035 0" damping="1"/>
                      <geom type="mesh" mesh="link8"/>
                    </body>
                  </body>
                </body>
              </body>
            </body>
          </body>
        </body>
      </body>
    </body>
  </worldbody>

  <actuator>
    <!-- Position servos with built-in PD control - much more stable -->
    <position name="servo1" joint="joint1" kp="200" kv="20"/>
    <position name="servo2" joint="joint2" kp="300" kv="30"/>
    <position name="servo3" joint="joint3" kp="250" kv="25"/>
    <position name="servo4" joint="joint4" kp="150" kv="15"/>
    <position name="servo5" joint="joint5" kp="150" kv="15"/>
    <position name="servo6" joint="joint6" kp="100" kv="10"/>
    <position name="gripper1" joint="joint7" kp="100"/>
    <position name="gripper2" joint="joint8" kp="100"/>
  </actuator>

  <sensor>
    <jointpos name="pos1" joint="joint1"/>
    <jointpos name="pos2" joint="joint2"/>
    <jointpos name="pos3" joint="joint3"/>
    <jointpos name="pos4" joint="joint4"/>
    <jointpos name="pos5" joint="joint5"/>
    <jointpos name="pos6" joint="joint6"/>
    <jointvel name="vel1" joint="joint1"/>
    <jointvel name="vel2" joint="joint2"/>
    <jointvel name="vel3" joint="joint3"/>
    <jointvel name="vel4" joint="joint4"/>
    <jointvel name="vel5" joint="joint5"/>
    <jointvel name="vel6" joint="joint6"/>
  </sensor>
</mujoco>
